Workbook
Name Cellule_1000: 'T4 B2-immo'!$D$18
Name Cellule_1001: 'T4 B2-immo'!$D$21
Name Cellule_1002: 'T4 B2-immo'!$D$22
Name Cellule_10022: 'T15 Encourag'!$C$28
Name Cellule_10023: 'T15 Encourag'!$C$29
Name Cellule_10024: 'T15 Encourag'!$D$28
Name Cellule_10025: 'T15 Encourag'!$D$29
Name Cellule_10026: 'T15 Encourag'!$E$28
Name Cellule_10027: 'T15 Encourag'!$E$29
Name Cellule_10028: 'T15 Encourag'!$E$21
Name Cellule_10029: 'T15 Encourag'!$E$22
Name Cellule_1003: 'T4 B2-immo'!$D$23
Name Cellule_1004: 'T4 B2-immo'!$D$24
Name Cellule_10040: 'T15 Encourag'!$C$21
Name Cellule_10041: 'T15 Encourag'!$C$22
Name Cellule_10042: 'T15 Encourag'!$D$21
Name Cellule_10043: 'T15 Encourag'!$D$22
Name Cellule_1005: 'T4 B2-immo'!$D$27
Name Cellule_1006: 'T4 B2-immo'!$D$25
Name Cellule_10061_1: 'T16 Amort'!$A$24
Name Cellule_10061_10: 'T16 Amort'!$A$33
Name Cellule_10061_2: 'T16 Amort'!$A$25
Name Cellule_10061_3: 'T16 Amort'!$A$26
Name Cellule_10061_4: 'T16 Amort'!$A$27
Name Cellule_10061_5: 'T16 Amort'!$A$28
Name Cellule_10061_6: 'T16 Amort'!$A$29
Name Cellule_10061_7: 'T16 Amort'!$A$30
Name Cellule_10061_8: 'T16 Amort'!$A$31
Name Cellule_10061_9: 'T16 Amort'!$A$32
Name Cellule_10064: 'T4 B2-immo'!$B$9
Name Cellule_10065: 'T4 B2-immo'!$C$9
Name Cellule_10066: 'T4 B2-immo'!$D$9
Name Cellule_10067: 'T4 B2-immo'!$E$9
Name Cellule_10068: 'T4 B2-immo'!$F$9
Name Cellule_10069: 'T4 B2-immo'!$G$9
Name Cellule_1007: 'T4 B2-immo'!$D$26
Name Cellule_10070: 'T4 B2-immo'!$H$9
Name Cellule_10071: 'T4 B2-immo'!$I$9
Name Cellule_10073: 'T4 B2-immo'!$B$14
Name Cellule_10074: 'T4 B2-immo'!$C$14
Name Cellule_10075: 'T4 B2-immo'!$D$14
Name Cellule_10076: 'T4 B2-immo'!$E$14
Name Cellule_10077: 'T4 B2-immo'!$F$14
Name Cellule_10078: 'T4 B2-immo'!$G$14
Name Cellule_10079: 'T4 B2-immo'!$H$14
Name Cellule_1008: 'T4 B2-immo'!$E$10
Name Cellule_10080: 'T4 B2-immo'!$I$14
Name Cellule_10082: 'T4 B2-immo'!$B$20
Name Cellule_10083: 'T4 B2-immo'!$C$20
Name Cellule_10084: 'T4 B2-immo'!$D$20
Name Cellule_10085: 'T4 B2-immo'!$E$20
Name Cellule_10086: 'T4 B2-immo'!$F$20
Name Cellule_10087: 'T4 B2-immo'!$G$20
Name Cellule_10088: 'T4 B2-immo'!$H$20
Name Cellule_10089: 'T4 B2-immo'!$I$20
Name Cellule_1009: 'T4 B2-immo'!$E$11
Name Cellule_10091: 'T6 TB11'!$D$28
Name Cellule_1010: 'T4 B2-immo'!$E$12
Name Cellule_1011: 'T4 B2-immo'!$E$15
Name Cellule_1012: 'T4 B2-immo'!$E$16

Sheet Feuil1
A12: Identification société
H15: T 5 : ESG

Sheet Identification
A7: Dénomination sociale | B7: CLUB DE COMPTA
A9: Siège social | B9: MAROC
A11: Exercice social | B11: du | C11: 44562 | D11: au | E11: 31/12/2022
A13: IF | C13: 7777777
A15: TP
A17: RC | C17: 7777

Sheet Couverture Etats de synthèse
B7: Etats de synthèse
A13: DECLARATION AU TITRE DE L'ANNEE
B15: Du | C15: =Identification!C11 -> 44562 | D15: Au | E15: =Identification!E11 -> 31/12/2022
A21: Raison sociale : | C21: =Identification!B7 -> CLUB DE COMPTA
A23: Article I.F. | F23: =Identification!C13 -> 7777777
A27: Adresse : | C27: =Identification!B9 -> MAROC
A31: R.C. n° | C31: =Identification!C17 -> 7777
A32: Taxe Professionnelle n° | C32: =Identification!C15 -> 0
E36: A ………………… Le …/…/……..
E38: Signature
A44: CADRE RESERVE A L'ADMINISTRATION
A46: Numéro d'Enregistrement de la Déclaration : .............................................
A48: Date : ...................................................
E49: Signature
A54: N.B. : Les tableaux de 1 à 14 sont conformes aux états prévus par la loi n° 9-88 relative aux obligations
A55: comptables des commerçants promulguée par le Dahir n° 1,92,138 du 3 Joumada II 1413 (15,12,1992)

Sheet Couverture
L1: Modèle 100/IS/N
A4: PIECES ANNEXES A LA
A5: DECLARATION FISCALE
A7: IMPOT SUR LES SOCIETES
A9: (Modèle Comptable Normal)
A13: DECLARATION AU TITRE DE L'ANNEE
B15: Du | C15: =Identification!C11 -> 44562 | D15: Au | E15: =Identification!E11 -> 31/12/2022
A21: Raison sociale : | C21: =Identification!B7 -> CLUB DE COMPTA
A23: Article I.F. | F23: =Identification!B7 -> CLUB DE COMPTA
A27: Adresse : | B27: =Identification!B9 -> MAROC
A31: R.C. n° | B31: =Identification!C17 -> 7777
A32: Taxe Professionnelle n° | B32: =Identification!C15 -> 0
E36: ='Couverture Etats de synthèse'!E36 -> A ………………… Le …/…/……..
E38: Signature
A44: CADRE RESERVE A L'ADMINISTRATION
A46: Numéro d'Enregistrement de la Déclaration : .............................................
A48: Date : ...................................................
E49: Signature
A54: N.B. : Les tableaux de 1 à 14 sont conformes aux états prévus par la loi n° 9-88 relative aux obligations
A55: comptables des commerçants promulguée par le Dahir n° 1,92,138 du 3 Joumada II 1413 (15,12,1992)

Sheet Programme
A1: N° Odre | B1: Tableau | C1: A | D1: B | E1: C | F1: D | G1: E | H1: F | I1: G
A2: 1 | B2: PG | C2: <?xml version="1.0" encoding="utf-8"?>
A3: =+A2+1 -> 2 | B3: PG | C3: <Liasse>
A4: =+A3+1 -> 3 | B4: PG | D4: <modele>
A5: =+A4+1 -> 4 | B5: PG | E5: <id>1</id>
A6: =+A5+1 -> 5 | B6: PG | D6: </modele>
A7: =+A6+1 -> 6 | B7: PG | D7: <resultatFiscal>
A8: =+A7+1 -> 7 | B8: PG | D8: =CONCATENATE("<identifiantFiscal>",Identification!C13,"</identifiantFiscal>") -> <identifiantFiscal>7777777</identifiantFiscal>
A9: =+A8+1 -> 8 | B9: PG | E9: =CONCATENATE("<exerciceFiscalDu>",CONCATENATE(YEAR(Identification!C11),"-0",MONTH(Identification!C11),"-0",DAY(Identification!C11)),"</exerciceFiscalDu>") -> <exerciceFiscalDu>2022-01-01</exerciceFiscalDu>
A10: =+A9+1 -> 9 | B10: PG | E10: =CONCATENATE("<exerciceFiscalAu>",CONCATENATE(YEAR(Identification!E11),"-",MONTH(Identification!E11),"-",DAY(Identification!E11)),"</exerciceFiscalAu>") -> <exerciceFiscalAu>2022-12-31</exerciceFiscalAu>
A11: =+A10+1 -> 10 | B11: PG | D11: </resultatFiscal>
A12: =+A11+1 -> 11 | B12: PG | D12: <!-- Partie 2 : Liasse Fiscale -->
A13: =+A12+1 -> 12 | B13: PG | D13: <!-- Les valeurs de chaque tableau de la liasse -->
A14: =+A13+1 -> 13 | B14: PG | D14: <groupeValeursTableau>
A15: =+A14+1 -> 14 | B15: PG | E15: <ValeursTableau>
A16: =+A15+1 -> 15 | B16: T01 Actif | F16: <tableau><id>2</id></tableau>
A17: =+A16+1 -> 16 | B17: T01 Actif | F17: <groupeValeurs>
A18: =+A17+1 -> 17 | B18: T01 Actif | G18: <ValeurCellule>
A19: =+A18+1 -> 18 | B19: T01 Actif | H19: <cellule>
A20: =+A19+1 -> 19 | B20: T01 Actif | I20: <codeEdi>238</codeEdi>
A21: =+A20+1 -> 20 | B21: T01 Actif | H21: </cellule>
A22: =+A21+1 -> 21 | B22: T01 Actif | H22: =CONCATENATE("<valeur>",Cellule_238,"</valeur>") -> <valeur>5000</valeur>
A23: =+A22+1 -> 22 | B23: T01 Actif | G23: </ValeurCellule>
A24: =+A23+1 -> 23 | B24: T01 Actif | G24: <ValeurCellule>
A25: =+A24+1 -> 24 | B25: T01 Actif | H25: <cellule>
A26: =+A25+1 -> 25 | B26: T01 Actif | I26: <codeEdi>239</codeEdi>
A27: =+A26+1 -> 26 | B27: T01 Actif | H27: </cellule>
A28: =+A27+1 -> 27 | B28: T01 Actif | H28: =CONCATENATE("<valeur>",Cellule_239,"</valeur>") -> <valeur>0</valeur>
A29: =+A28+1 -> 28 | B29: T01 Actif | G29: </ValeurCellule>
A30: =+A29+1 -> 29 | B30: T01 Actif | G30: <ValeurCellule>
A31: =+A30+1 -> 30 | B31: T01 Actif | H31: <cellule>
A32: =+A31+1 -> 31 | B32: T01 Actif | I32: <codeEdi>240</codeEdi>
A33: =+A32+1 -> 32 | B33: T01 Actif | H33: </cellule>
A34: =+A33+1 -> 33 | B34: T01 Actif | H34: =CONCATENATE("<valeur>",Cellule_240,"</valeur>") -> <valeur>0</valeur>
A35: =+A34+1 -> 34 | B35: T01 Actif | G35: </ValeurCellule>
A36: =+A35+1 -> 35 | B36: T01 Actif | G36: <ValeurCellule>
A37: =+A36+1 -> 36 | B37: T01 Actif | H37: <cellule>
A38: =+A37+1 -> 37 | B38: T01 Actif | I38: <codeEdi>497</codeEdi>
A39: =+A38+1 -> 38 | B39: T01 Actif | H39: </cellule>
A40: =+A39+1 -> 39 | B40: T01 Actif | H40: =CONCATENATE("<valeur>",Cellule_497,"</valeur>") -> <valeur>5000</valeur>
...

Sheet Xml
A1: =CONCATENATE(Programme!C2,Programme!D2,Programme!E2,Programme!F2,Programme!G2,Programme!H2,Programme!I2) -> <?xml version="1.0" encoding="utf-8"?>
A2: =CONCATENATE(Programme!C3,Programme!D3,Programme!E3,Programme!F3,Programme!G3,Programme!H3,Programme!I3) -> <Liasse>
A3: =CONCATENATE(Programme!C4,Programme!D4,Programme!E4,Programme!F4,Programme!G4,Programme!H4,Programme!I4) -> <modele>
A4: =CONCATENATE(Programme!C5,Programme!D5,Programme!E5,Programme!F5,Programme!G5,Programme!H5,Programme!I5) -> <id>1</id>
A5: =CONCATENATE(Programme!C6,Programme!D6,Programme!E6,Programme!F6,Programme!G6,Programme!H6,Programme!I6) -> </modele>
A6: =CONCATENATE(Programme!C7,Programme!D7,Programme!E7,Programme!F7,Programme!G7,Programme!H7,Programme!I7) -> <resultatFiscal>
A7: =CONCATENATE(Programme!C8,Programme!D8,Programme!E8,Programme!F8,Programme!G8,Programme!H8,Programme!I8) -> <identifiantFiscal>7777777</identifiantFiscal>
A8: =CONCATENATE(Programme!C9,Programme!D9,Programme!E9,Programme!F9,Programme!G9,Programme!H9,Programme!I9) -> <exerciceFiscalDu>2022-01-01</exerciceFiscalDu>
A9: =CONCATENATE(Programme!C10,Programme!D10,Programme!E10,Programme!F10,Programme!G10,Programme!H10,Programme!I10) -> <exerciceFiscalAu>2022-12-31</exerciceFiscalAu>
A10: =CONCATENATE(Programme!C11,Programme!D11,Programme!E11,Programme!F11,Programme!G11,Programme!H11,Programme!I11) -> </resultatFiscal>
A11: =CONCATENATE(Programme!C12,Programme!D12,Programme!E12,Programme!F12,Programme!G12,Programme!H12,Programme!I12) -> <!-- Partie 2 : Liasse Fiscale -->
A12: =CONCATENATE(Programme!C13,Programme!D13,Programme!E13,Programme!F13,Programme!G13,Programme!H13,Programme!I13) -> <!-- Les valeurs de chaque tableau de la liasse -->
... A11738: =CONCATENATE(Programme!C11739,Programme!D11739,Programme!E11739,Programme!F11739,Programme!G11739,Programme!H11739,Programme!I11739) -> </Liasse>

Sheet Balance N
A1: Compte | B1: Libellé | C1: Débit Période N | D1: Crédit Période N | E1: Solde Débit N | F1: Solde Crédit N
A2: 11110000 | B2: CAPITAL | C2: 0 | D2: 100000 | E2: 0 | F2: 100000
A3: 11690000 | B3: ANV DEBITEUR | C3: 18918.67 | D3: 0 | E3: 18918.67 | F3: 0
A4: 14810000 | B4: WAFASALAF | C4: 93239.76 | D4: 928651.92 | E4: 0 | F4: 835412.16
A5: 14810100 | B5: RCI FIN | C5: 11938.55 | D5: 100000 | E5: 0 | F5: 88061.45
A6: 14820300 | B6: SOFAC CREDIT | C6: 0 | D6: 81942 | E6: 0 | F6: 81942
A7: 21110000 | B7: Frais constitution | C7: 5000 | D7: 0 | E7: 5000 | F7: 0
A8: 23232000 | B8: MATERIEL ET OUTILLAGE | C8: 9700 | D8: 0 | E8: 9700 | F8: 0
A9: 23400000 | B9: MATRIEL DE TRANSPORT | C9: 1578827.6 | D9: 0 | E9: 1578827.6 | F9: 0
A10: 28110000 | B10: Amort frais constitution | C10: 0 | D10: 2360.87 | E10: 0 | F10: 2360.87
A11: 28322000 | B11: AMOT MATERIEL ET OULILLAGE | C11: 0 | D11: 1215 | E11: 0 | F11: 1215
A12: 28340000 | B12: AMPORT MAT DE TRANSP | C12: 0 | D12: 169962.26 | E12: 0 | F12: 169962.26
A13: 34110000 | B13: Frs avances et acompte | C13: 504198.25 | D13: 504198.25 | E13: 0 | F13: 0
... A32: 61455000 | B32: TELEPHONE | C32: 3306 | D32: 0 | E32: 3306 | F32: 0
A33: 61470000 | B33: frais bancaire | C33: =6139.91+1466.39 -> 7606.3 | D33: 0 | E33: 7606.3 | F33: 0
A34: 61610000 | B34: impot et taxes | C34: 17477 | D34: 0 | E34: 17477 | F34: 0
A35: 61673000 | B35: VIGNETTE | C35: 10710 | D35: 0 | E35: 10710 | F35: 0
A36: 61710000 | B36: SALAIRE BRUT | C36: 28731 | D36: 0 | E36: 28731 | F36: 0
A37: 61740000 | B37: COT P P | C37: 5445.55 | D37: 0 | E37: 5445.55 | F37: 0
A38: 61911000 | B38: DEA FRAIS CONSTITUTION | C38: 1666.5 | D38: 0 | E38: 1666.5 | F38: 0
A39: 61940000 | B39: AMORT MAT CORPORELLE | C39: 171177.26 | D39: 0 | E39: 171177.26 | F39: 0
A40: 63111000 | B40: INTERETS SUR EMPRUNETS | C40: 43957.11 | D40: 0 | E40: 43957.11 | F40: 0
A42: 67010000 | B42: IMPOT SUR LE BENIFICE | C42: 2384 | D42: 0 | E42: 2384 | F42: 0
A43: 71240000 | B43: vente prod prestation de services | C43: 0 | D43: 381666.67 | E43: 0 | F43: 381666.67
A44: 89000000 | B44: Bilan d'ouverture | C44: 18918.67 | D44: 18918.67 | E44: 0 | F44: 0

Sheet Balance N-1
A1: Compte | B1: Libellé | C1: Débit Période | D1: Crédit Période | E1: Débit Cumulé | F1: Crédit Cumulé | G1: Solde Cumulé
A2: 11110000 | B2: CAPITAL | C2: 0 | D2: 100000 | E2: 0 | F2: 100000
A3: 21110000 | B3: Frais constitution | C3: 5000 | D3: 0 | E3: 5000 | F3: 0
A4: 28110000 | B4: Amort frais constitution | C4: 0 | D4: 694.37 | E4: 0 | F4: 694.37
A5: 34550300 | B5: TVA10 % | C5: 34.53 | D5: 0 | E5: 34.53 | F5: 0
A6: 44320000 | B6: SALAIRE NET | C6: 10000 | D6: 10000 | E6: 0 | F6: 0
A7: 44410000 | B7: COT CNSS | C7: 1073 | D7: 2146 | E7: 0 | F7: 1073
A8: 44450000 | B8: COT AMO | C8: 318.5 | D8: 637 | E8: 0 | F8: 318.5
A9: 44525000 | B9: IR | C9: 0 | D9: 88 | E9: 0 | F9: 88
A10: 44630000 | B10: COMPTE COURANT D'ASSOCIE | C10: 340475.8 | D10: 574000.8 | E10: 0 | F10: 233525
A11: 51410000 | B11: ATTIJARIWAFA BANK | C11: 469000.8 | D11: 246155.13 | E11: 222845.67 | F11: 0
A12: 51610000 | B12: CAISSE | C12: 108900 | D12: 20000 | E12: 88900 | F12: 0
A13: 61312000 | B13: loyer | C13: 5000 | D13: 0 | E13: 5000 | F13: 0
... A17: 61911000 | B17: DEA FRAIS CONSTITUTION | C17: 694.37 | D17: 0 | E17: 694.37 | F17: 0

Sheet Balance N Retraitée
A1: Numero | B1: Libellé | C1: SD N-1 | D1: SC N-1 | E1: Débit Période | F1: Crédit Période | G1: SD N | H1: SC N | K1: Débit P. | L1: Crédit P. | M1: Solde
A2: =FIXED('Balance N'!A2,0,1) -> 11110000 | B2: =+'Balance N'!B2 -> CAPITAL | C2: =ROUND('Balance N'!#REF!,2) -> #REF! | D2: =ROUND('Balance N'!#REF!,2) -> #REF! | E2: =ROUND('Balance N'!C2,2) -> 0 | F2: =ROUND('Balance N'!D2,2) -> 100000 | G2: =ROUND('Balance N'!E2,2) -> 0 | H2: =ROUND('Balance N'!F2,2) -> 100000 | I2: =MID(A2,1,1) -> 1 | J2: 1 | K2: =SUMIF(I:I,J2,C:C) -> #REF! | L2: =SUMIF(I:I,J2,D:D) -> #REF! | M2: =+K2-L2 -> #REF! | N2: =+M2 -> #REF!
A3: =FIXED('Balance N'!A3,0,1) -> 11690000 | B3: =+'Balance N'!B3 -> ANV DEBITEUR | C3: =ROUND('Balance N'!#REF!,2) -> #REF! | D3: =ROUND('Balance N'!#REF!,2) -> #REF! | E3: =ROUND('Balance N'!C3,2) -> 18918.67 | F3: =ROUND('Balance N'!D3,2) -> 0 | G3: =ROUND('Balance N'!E3,2) -> 18918.67 | H3: =ROUND('Balance N'!F3,2) -> 0 | I3: =MID(A3,1,1) -> 1 | J3: 2 | K3: =SUMIF(I:I,J3,C:C) -> #REF! | L3: =SUMIF(I:I,J3,D:D) -> #REF! | M3: =+K3-L3 -> #REF! | N3: =+N2+M3 -> #REF!
A4: =FIXED('Balance N'!A4,0,1) -> 14810000 | B4: =+'Balance N'!B4 -> WAFASALAF | C4: =ROUND('Balance N'!#REF!,2) -> #REF! | D4: =ROUND('Balance N'!#REF!,2) -> #REF! | E4: =ROUND('Balance N'!C4,2) -> 93239.76 | F4: =ROUND('Balance N'!D4,2) -> 928651.92 | G4: =ROUND('Balance N'!E4,2) -> 0 | H4: =ROUND('Balance N'!F4,2) -> 835412.16 | I4: =MID(A4,1,1) -> 1 | J4: 3 | K4: =SUMIF(I:I,J4,C:C) -> #REF! | L4: =SUMIF(I:I,J4,D:D) -> #REF! | M4: =+K4-L4 -> #REF! | N4: =+N3+M4 -> #REF!
A5: =FIXED('Balance N'!A5,0,1) -> 14810100 | B5: =+'Balance N'!B5 -> RCI FIN | C5: =ROUND('Balance N'!#REF!,2) -> #REF! | D5: =ROUND('Balance N'!#REF!,2) -> #REF! | E5: =ROUND('Balance N'!C5,2) -> 11938.55 | F5: =ROUND('Balance N'!D5,2) -> 100000 | G5: =ROUND('Balance N'!E5,2) -> 0 | H5: =ROUND('Balance N'!F5,2) -> 88061.45 | I5: =MID(A5,1,1) -> 1 | J5: 4 | K5: =SUMIF(I:I,J5,C:C) -> #REF! | L5: =SUMIF(I:I,J5,D:D) -> #REF! | M5: =+K5-L5 -> #REF! | N5: =+N4+M5 -> #REF!
A6: =FIXED('Balance N'!A6,0,1) -> 14820300 | B6: =+'Balance N'!B6 -> SOFAC CREDIT | C6: =ROUND('Balance N'!#REF!,2) -> #REF! | D6: =ROUND('Balance N'!#REF!,2) -> #REF! | E6: =ROUND('Balance N'!C6,2) -> 0 | F6: =ROUND('Balance N'!D6,2) -> 81942 | G6: =ROUND('Balance N'!E6,2) -> 0 | H6: =ROUND('Balance N'!F6,2) -> 81942 | I6: =MID(A6,1,1) -> 1 | J6: 5 | K6: =SUMIF(I:I,J6,C:C) -> #REF! | L6: =SUMIF(I:I,J6,D:D) -> #REF! | M6: =+K6-L6 -> #REF! | N6: =+N5+M6 -> #REF! | O6: =SUM(K2:K6) -> #REF! | P6: =SUM(L2:L6) -> #REF! | Q6: =+O6-P6 -> #REF!
A7: =FIXED('Balance N'!A7,0,1) -> 21110000 | B7: =+'Balance N'!B7 -> Frais constitution | C7: =ROUND('Balance N'!#REF!,2) -> #REF! | D7: =ROUND('Balance N'!#REF!,2) -> #REF! | E7: =ROUND('Balance N'!C7,2) -> 5000 | F7: =ROUND('Balance N'!D7,2) -> 0 | G7: =ROUND('Balance N'!E7,2) -> 5000 | H7: =ROUND('Balance N'!F7,2) -> 0 | I7: =MID(A7,1,1) -> 2 | J7: 6 | K7: =SUMIF(I:I,J7,C:C) -> #REF! | L7: =SUMIF(I:I,J7,D:D) -> #REF! | M7: =+K7-L7 -> #REF! | N7: =M7 -> #REF!
A8: =FIXED('Balance N'!A8,0,1) -> 23232000 | B8: =+'Balance N'!B8 -> MATERIEL ET OUTILLAGE | C8: =ROUND('Balance N'!#REF!,2) -> #REF! | D8: =ROUND('Balance N'!#REF!,2) -> #REF! | E8: =ROUND('Balance N'!C8,2) -> 9700 | F8: =ROUND('Balance N'!D8,2) -> 0 | G8: =ROUND('Balance N'!E8,2) -> 9700 | H8: =ROUND('Balance N'!F8,2) -> 0 | I8: =MID(A8,1,1) -> 2 | J8: 7 | K8: =SUMIF(I:I,J8,C:C) -> #REF! | L8: =SUMIF(I:I,J8,D:D) -> #REF! | M8: =+K8-L8 -> #REF! | N8: =+N7+M8 -> #REF!
A9: =FIXED('Balance N'!A9,0,1) -> 23400000 | B9: =+'Balance N'!B9 -> MATRIEL DE TRANSPORT | C9: =ROUND('Balance N'!#REF!,2) -> #REF! | D9: =ROUND('Balance N'!#REF!,2) -> #REF! | E9: =ROUND('Balance N'!C9,2) -> 1578827.6 | F9: =ROUND('Balance N'!D9,2) -> 0 | G9: =ROUND('Balance N'!E9,2) -> 1578827.6 | H9: =ROUND('Balance N'!F9,2) -> 0 | I9: =MID(A9,1,1) -> 2 | J9: 8 | K9: =SUMIF(I:I,J9,C:C) -> #REF! | L9: =SUMIF(I:I,J9,D:D) -> #REF! | M9: =+K9-L9 -> #REF! | O9: =SUM(K7:K9) -> #REF! | P9: =SUM(L7:L9) -> #REF! | Q9: =+O9-P9 -> #REF!
A10: =FIXED('Balance N'!A10,0,1) -> 28110000 | B10: =+'Balance N'!B10 -> Amort frais constitution | C10: =ROUND('Balance N'!#REF!,2) -> #REF! | D10: =ROUND('Balance N'!#REF!,2) -> #REF! | E10: =ROUND('Balance N'!C10,2) -> 0 | F10: =ROUND('Balance N'!D10,2) -> 2360.87 | G10: =ROUND('Balance N'!E10,2) -> 0 | H10: =ROUND('Balance N'!F10,2) -> 2360.87 | I10: =MID(A10,1,1) -> 2 | J10: Total | K10: =SUM(K2:K9) -> #REF! | L10: =SUM(L2:L9) -> #REF! | M10: =SUM(M2:M9) -> #REF!
A11: =FIXED('Balance N'!A11,0,1) -> 28322000 | B11: =+'Balance N'!B11 -> AMOT MATERIEL ET OULILLAGE | C11: =ROUND('Balance N'!#REF!,2) -> #REF! | D11: =ROUND('Balance N'!#REF!,2) -> #REF! | E11: =ROUND('Balance N'!C11,2) -> 0 | F11: =ROUND('Balance N'!D11,2) -> 1215 | G11: =ROUND('Balance N'!E11,2) -> 0 | H11: =ROUND('Balance N'!F11,2) -> 1215 | I11: =MID(A11,1,1) -> 2
A12: =FIXED('Balance N'!A12,0,1) -> 28340000 | B12: =+'Balance N'!B12 -> AMPORT MAT DE TRANSP | C12: =ROUND('Balance N'!#REF!,2) -> #REF! | D12: =ROUND('Balance N'!#REF!,2) -> #REF! | E12: =ROUND('Balance N'!C12,2) -> 0 | F12: =ROUND('Balance N'!D12,2) -> 169962.26 | G12: =ROUND('Balance N'!E12,2) -> 0 | H12: =ROUND('Balance N'!F12,2) -> 169962.26 | I12: =MID(A12,1,1) -> 2
A13: =FIXED('Balance N'!A13,0,1) -> 34110000 | B13: =+'Balance N'!B13 -> Frs avances et acompte | C13: =ROUND('Balance N'!#REF!,2) -> #REF! | D13: =ROUND('Balance N'!#REF!,2) -> #REF! | E13: =ROUND('Balance N'!C13,2) -> 504198.25 | F13: =ROUND('Balance N'!D13,2) -> 504198.25 | G13: =ROUND('Balance N'!E13,2) -> 0 | H13: =ROUND('Balance N'!F13,2) -> 0 | I13: =MID(A13,1,1) -> 3
A14: =FIXED('Balance N'!A14,0,1) -> 34210000 | B14: =+'Balance N'!B14 -> clients collectiive | C14: =ROUND('Balance N'!#REF!,2) -> #REF! | D14: =ROUND('Balance N'!#REF!,2) -> #REF! | E14: =ROUND('Balance N'!C14,2) -> 483000 | F14: =ROUND('Balance N'!D14,2) -> 195000 | G14: =ROUND('Balance N'!E14,2) -> 288000 | H14: =ROUND('Balance N'!F14,2) -> 0 | I14: =MID(A14,1,1) -> 3
A15: =FIXED('Balance N'!A15,0,1) -> 34550100 | B15: =+'Balance N'!B15 -> tva 20% | C15: =ROUND('Balance N'!#REF!,2) -> #REF! | D15: =ROUND('Balance N'!#REF!,2) -> #REF! | E15: =ROUND('Balance N'!C15,2) -> 42169.66 | F15: =ROUND('Balance N'!D15,2) -> 22567.97 | G15: =ROUND('Balance N'!E15,2) -> 19601.69 | H15: =ROUND('Balance N'!F15,2) -> 0 | I15: =MID(A15,1,1) -> 3
A16: =FIXED('Balance N'!A16,0,1) -> 34550300 | B16: =+'Balance N'!B16 -> TVA10 % | C16: =ROUND('Balance N'!#REF!,2) -> #REF! | D16: =ROUND('Balance N'!#REF!,2) -> #REF! | E16: =ROUND('Balance N'!C16,2) -> 4690.35 | F16: =ROUND('Balance N'!D16,2) -> 3491.32 | G16: =ROUND('Balance N'!E16,2) -> 1199.03 | H16: =ROUND('Balance N'!F16,2) -> 0 | I16: =MID(A16,1,1) -> 3
A17: =FIXED('Balance N'!A17,0,1) -> 34560000 | B17: =+'Balance N'!B17 -> CREDIT TVA | C17: =ROUND('Balance N'!#REF!,2) -> #REF! | D17: =ROUND('Balance N'!#REF!,2) -> #REF! | E17: =ROUND('Balance N'!C17,2) -> 3385.76 | F17: =ROUND('Balance N'!D17,2) -> 3385.76 | G17: =ROUND('Balance N'!E17,2) -> 0 | H17: =ROUND('Balance N'!F17,2) -> 0 | I17: =MID(A17,1,1) -> 3
A18: =FIXED('Balance N'!A18,0,1) -> 44110100 | B18: =+'Balance N'!B18 -> FOURNISSEUR LOCAUX | C18: =ROUND('Balance N'!#REF!,2) -> #REF! | D18: =ROUND('Balance N'!#REF!,2) -> #REF! | E18: =ROUND('Balance N'!C18,2) -> 1636170.1 | F18: =ROUND('Balance N'!D18,2) -> 1643743.3 | G18: =ROUND('Balance N'!E18,2) -> 0 | H18: =ROUND('Balance N'!F18,2) -> 7573.2 | I18: =MID(A18,1,1) -> 4
A19: =FIXED('Balance N'!A19,0,1) -> 44320000 | B19: =+'Balance N'!B19 -> SALAIRE NET | C19: =ROUND('Balance N'!#REF!,2) -> #REF! | D19: =ROUND('Balance N'!#REF!,2) -> #REF! | E19: =ROUND('Balance N'!C19,2) -> 26727 | F19: =ROUND('Balance N'!D19,2) -> 26727 | G19: =ROUND('Balance N'!E19,2) -> 0 | H19: =ROUND('Balance N'!F19,2) -> 0 | I19: =MID(A19,1,1) -> 4
A20: =FIXED('Balance N'!A20,0,1) -> 44410000 | B20: =+'Balance N'!B20 -> COT CNSS | C20: =ROUND('Balance N'!#REF!,2) -> #REF! | D20: =ROUND('Balance N'!#REF!,2) -> #REF! | E20: =ROUND('Balance N'!C20,2) -> 6006.57 | F20: =ROUND('Balance N'!D20,2) -> 6620.41 | G20: =ROUND('Balance N'!E20,2) -> 0 | H20: =ROUND('Balance N'!F20,2) -> 613.84 | I20: =MID(A20,1,1) -> 4
A21: =FIXED('Balance N'!A21,0,1) -> 44450000 | B21: =+'Balance N'!B21 -> COT AMO | C21: =ROUND('Balance N'!#REF!,2) -> #REF! | D21: =ROUND('Balance N'!#REF!,2) -> #REF! | E21: =ROUND('Balance N'!C21,2) -> 1782.97 | F21: =ROUND('Balance N'!D21,2) -> 1965.15 | G21: =ROUND('Balance N'!E21,2) -> 0 | H21: =ROUND('Balance N'!F21,2) -> 182.18 | I21: =MID(A21,1,1) -> 4
A22: =FIXED('Balance N'!A22,0,1) -> 44525000 | B22: =+'Balance N'!B22 -> IR | C22: =ROUND('Balance N'!#REF!,2) -> #REF! | D22: =ROUND('Balance N'!#REF!,2) -> #REF! | E22: =ROUND('Balance N'!C22,2) -> 0 | F22: =ROUND('Balance N'!D22,2) -> 343.49 | G22: =ROUND('Balance N'!E22,2) -> 0 | H22: =ROUND('Balance N'!F22,2) -> 343.49 | I22: =MID(A22,1,1) -> 4
... A614: =FIXED('Balance N'!A614,0,1) -> 0 | B614: =+'Balance N'!B614 -> 0 | C614: =ROUND('Balance N'!#REF!,2) -> #REF! | D614: =ROUND('Balance N'!#REF!,2) -> #REF! | E614: =ROUND('Balance N'!C614,2) -> 0 | F614: =ROUND('Balance N'!D614,2) -> 0 | G614: =ROUND('Balance N'!E614,2) -> 0 | H614: =ROUND('Balance N'!F614,2) -> 0 | I614: =MID(A614,1,1) -> 0
C615: =ROUND('Balance N'!#REF!,2) -> #REF! | D615: =ROUND('Balance N'!#REF!,2) -> #REF! | E615: =ROUND('Balance N'!C615,2) -> 0 | F615: =ROUND('Balance N'!D615,2) -> 0 | G615: =ROUND('Balance N'!E615,2) -> 0 | H615: =ROUND('Balance N'!F615,2) -> 0

Sheet Balance N-1 Retraitée
A1: Numero | B1: Libellé | C1: SD N-1 | D1: SC N-1 | E1: Débit Période | F1: Crédit Période | G1: SD N | H1: SC N | K1: Débit P. | L1: Crédit P. | M1: Solde
A2: =FIXED('Balance N-1'!A2,0,1) -> 11110000 | B2: =+'Balance N-1'!B2 -> CAPITAL | C2: =ROUND('Balance N-1'!#REF!,2) -> #REF! | D2: =ROUND('Balance N-1'!#REF!,2) -> #REF! | E2: =ROUND('Balance N-1'!C2,2) -> 0 | F2: =ROUND('Balance N-1'!D2,2) -> 100000 | G2: =ROUND('Balance N-1'!E2,2) -> 0 | H2: =ROUND('Balance N-1'!F2,2) -> 100000 | I2: =MID(A2,1,1) -> 1 | J2: 1 | K2: =SUMIF(I:I,J2,C:C) -> #REF! | L2: =SUMIF(I:I,J2,D:D) -> #REF! | M2: =+K2-L2 -> #REF! | N2: =+M2 -> #REF!
A3: =FIXED('Balance N-1'!A3,0,1) -> 21110000 | B3: =+'Balance N-1'!B3 -> Frais constitution | C3: =ROUND('Balance N-1'!#REF!,2) -> #REF! | D3: =ROUND('Balance N-1'!#REF!,2) -> #REF! | E3: =ROUND('Balance N-1'!C3,2) -> 5000 | F3: =ROUND('Balance N-1'!D3,2) -> 0 | G3: =ROUND('Balance N-1'!E3,2) -> 5000 | H3: =ROUND('Balance N-1'!F3,2) -> 0 | I3: =MID(A3,1,1) -> 2 | J3: 2 | K3: =SUMIF(I:I,J3,C:C) -> #REF! | L3: =SUMIF(I:I,J3,D:D) -> #REF! | M3: =+K3-L3 -> #REF! | N3: =+N2+M3 -> #REF!
A4: =FIXED('Balance N-1'!A4,0,1) -> 28110000 | B4: =+'Balance N-1'!B4 -> Amort frais constitution | C4: =ROUND('Balance N-1'!#REF!,2) -> #REF! | D4: =ROUND('Balance N-1'!#REF!,2) -> #REF! | E4: =ROUND('Balance N-1'!C4,2) -> 0 | F4: =ROUND('Balance N-1'!D4,2) -> 694.37 | G4: =ROUND('Balance N-1'!E4,2) -> 0 | H4: =ROUND('Balance N-1'!F4,2) -> 694.37 | I4: =MID(A4,1,1) -> 2 | J4: 3 | K4: =SUMIF(I:I,J4,C:C) -> #REF! | L4: =SUMIF(I:I,J4,D:D) -> #REF! | M4: =+K4-L4 -> #REF! | N4: =+N3+M4 -> #REF!
A5: =FIXED('Balance N-1'!A5,0,1) -> 34550300 | B5: =+'Balance N-1'!B5 -> TVA10 % | C5: =ROUND('Balance N-1'!#REF!,2) -> #REF! | D5: =ROUND('Balance N-1'!#REF!,2) -> #REF! | E5: =ROUND('Balance N-1'!C5,2) -> 34.53 | F5: =ROUND('Balance N-1'!D5,2) -> 0 | G5: =ROUND('Balance N-1'!E5,2) -> 34.53 | H5: =ROUND('Balance N-1'!F5,2) -> 0 | I5: =MID(A5,1,1) -> 3 | J5: 4 | K5: =SUMIF(I:I,J5,C:C) -> #REF! | L5: =SUMIF(I:I,J5,D:D) -> #REF! | M5: =+K5-L5 -> #REF! | N5: =+N4+M5 -> #REF!
A6: =FIXED('Balance N-1'!A6,0,1) -> 44320000 | B6: =+'Balance N-1'!B6 -> SALAIRE NET | C6: =ROUND('Balance N-1'!#REF!,2) -> #REF! | D6: =ROUND('Balance N-1'!#REF!,2) -> #REF! | E6: =ROUND('Balance N-1'!C6,2) -> 10000 | F6: =ROUND('Balance N-1'!D6,2) -> 10000 | G6: =ROUND('Balance N-1'!E6,2) -> 0 | H6: =ROUND('Balance N-1'!F6,2) -> 0 | I6: =MID(A6,1,1) -> 4 | J6: 5 | K6: =SUMIF(I:I,J6,C:C) -> #REF! | L6: =SUMIF(I:I,J6,D:D) -> #REF! | M6: =+K6-L6 -> #REF! | N6: =+N5+M6 -> #REF! | O6: =SUM(K2:K6) -> #REF! | P6: =SUM(L2:L6) -> #REF! | Q6: =+O6-P6 -> #REF!
A7: =FIXED('Balance N-1'!A7,0,1) -> 44410000 | B7: =+'Balance N-1'!B7 -> COT CNSS | C7: =ROUND('Balance N-1'!#REF!,2) -> #REF! | D7: =ROUND('Balance N-1'!#REF!,2) -> #REF! | E7: =ROUND('Balance N-1'!C7,2) -> 1073 | F7: =ROUND('Balance N-1'!D7,2) -> 2146 | G7: =ROUND('Balance N-1'!E7,2) -> 0 | H7: =ROUND('Balance N-1'!F7,2) -> 1073 | I7: =MID(A7,1,1) -> 4 | J7: 6 | K7: =SUMIF(I:I,J7,C:C) -> #REF! | L7: =SUMIF(I:I,J7,D:D) -> #REF! | M7: =+K7-L7 -> #REF! | N7: =M7 -> #REF!
A8: =FIXED('Balance N-1'!A8,0,1) -> 44450000 | B8: =+'Balance N-1'!B8 -> COT AMO | C8: =ROUND('Balance N-1'!#REF!,2) -> #REF! | D8: =ROUND('Balance N-1'!#REF!,2) -> #REF! | E8: =ROUND('Balance N-1'!C8,2) -> 318.5 | F8: =ROUND('Balance N-1'!D8,2) -> 637 | G8: =ROUND('Balance N-1'!E8,2) -> 0 | H8: =ROUND('Balance N-1'!F8,2) -> 318.5 | I8: =MID(A8,1,1) -> 4 | J8: 7 | K8: =SUMIF(I:I,J8,C:C) -> 0 | L8: =SUMIF(I:I,J8,D:D) -> 0 | M8: =+K8-L8 -> 0 | N8: =+N7+M8 -> #REF!
A9: =FIXED('Balance N-1'!A9,0,1) -> 44525000 | B9: =+'Balance N-1'!B9 -> IR | C9: =ROUND('Balance N-1'!#REF!,2) -> #REF! | D9: =ROUND('Balance N-1'!#REF!,2) -> #REF! | E9: =ROUND('Balance N-1'!C9,2) -> 0 | F9: =ROUND('Balance N-1'!D9,2) -> 88 | G9: =ROUND('Balance N-1'!E9,2) -> 0 | H9: =ROUND('Balance N-1'!F9,2) -> 88 | I9: =MID(A9,1,1) -> 4 | J9: 8 | K9: =SUMIF(I:I,J9,C:C) -> 0 | L9: =SUMIF(I:I,J9,D:D) -> 0 | M9: =+K9-L9 -> 0 | O9: =SUM(K7:K9) -> #REF! | P9: =SUM(L7:L9) -> #REF! | Q9: =+O9-P9 -> #REF!
A10: =FIXED('Balance N-1'!A10,0,1) -> 44630000 | B10: =+'Balance N-1'!B10 -> COMPTE COURANT D'ASSOCIE | C10: =ROUND('Balance N-1'!#REF!,2) -> #REF! | D10: =ROUND('Balance N-1'!#REF!,2) -> #REF! | E10: =ROUND('Balance N-1'!C10,2) -> 340475.8 | F10: =ROUND('Balance N-1'!D10,2) -> 574000.8 | G10: =ROUND('Balance N-1'!E10,2) -> 0 | H10: =ROUND('Balance N-1'!F10,2) -> 233525 | I10: =MID(A10,1,1) -> 4 | J10: Total | K10: =SUM(K2:K9) -> #REF! | L10: =SUM(L2:L9) -> #REF! | M10: =SUM(M2:M9) -> #REF!
A11: =FIXED('Balance N-1'!A11,0,1) -> 51410000 | B11: =+'Balance N-1'!B11 -> ATTIJARIWAFA BANK | C11: =ROUND('Balance N-1'!#REF!,2) -> #REF! | D11: =ROUND('Balance N-1'!#REF!,2) -> #REF! | E11: =ROUND('Balance N-1'!C11,2) -> 469000.8 | F11: =ROUND('Balance N-1'!D11,2) -> 246155.13 | G11: =ROUND('Balance N-1'!E11,2) -> 222845.67 | H11: =ROUND('Balance N-1'!F11,2) -> 0 | I11: =MID(A11,1,1) -> 5
A12: =FIXED('Balance N-1'!A12,0,1) -> 51610000 | B12: =+'Balance N-1'!B12 -> CAISSE | C12: =ROUND('Balance N-1'!#REF!,2) -> #REF! | D12: =ROUND('Balance N-1'!#REF!,2) -> #REF! | E12: =ROUND('Balance N-1'!C12,2) -> 108900 | F12: =ROUND('Balance N-1'!D12,2) -> 20000 | G12: =ROUND('Balance N-1'!E12,2) -> 88900 | H12: =ROUND('Balance N-1'!F12,2) -> 0 | I12: =MID(A12,1,1) -> 5
A13: =FIXED('Balance N-1'!A13,0,1) -> 61312000 | B13: =+'Balance N-1'!B13 -> loyer | C13: =ROUND('Balance N-1'!#REF!,2) -> #REF! | D13: =ROUND('Balance N-1'!#REF!,2) -> #REF! | E13: =ROUND('Balance N-1'!C13,2) -> 5000 | F13: =ROUND('Balance N-1'!D13,2) -> 0 | G13: =ROUND('Balance N-1'!E13,2) -> 5000 | H13: =ROUND('Balance N-1'!F13,2) -> 0 | I13: =MID(A13,1,1) -> 6
A14: =FIXED('Balance N-1'!A14,0,1) -> 61470000 | B14: =+'Balance N-1'!B14 -> frais bancaire | C14: =ROUND('Balance N-1'!#REF!,2) -> #REF! | D14: =ROUND('Balance N-1'!#REF!,2) -> #REF! | E14: =ROUND('Balance N-1'!C14,2) -> 353.3 | F14: =ROUND('Balance N-1'!D14,2) -> 0 | G14: =ROUND('Balance N-1'!E14,2) -> 353.3 | H14: =ROUND('Balance N-1'!F14,2) -> 0 | I14: =MID(A14,1,1) -> 6
A15: =FIXED('Balance N-1'!A15,0,1) -> 61710000 | B15: =+'Balance N-1'!B15 -> SALAIRE BRUT | C15: =ROUND('Balance N-1'!#REF!,2) -> #REF! | D15: =ROUND('Balance N-1'!#REF!,2) -> #REF! | E15: =ROUND('Balance N-1'!C15,2) -> 10762 | F15: =ROUND('Balance N-1'!D15,2) -> 0 | G15: =ROUND('Balance N-1'!E15,2) -> 10762 | H15: =ROUND('Balance N-1'!F15,2) -> 0 | I15: =MID(A15,1,1) -> 6
A16: =FIXED('Balance N-1'!A16,0,1) -> 61740000 | B16: =+'Balance N-1'!B16 -> COT P P | C16: =ROUND('Balance N-1'!#REF!,2) -> #REF! | D16: =ROUND('Balance N-1'!#REF!,2) -> #REF! | E16: =ROUND('Balance N-1'!C16,2) -> 2109 | F16: =ROUND('Balance N-1'!D16,2) -> 0 | G16: =ROUND('Balance N-1'!E16,2) -> 2109 | H16: =ROUND('Balance N-1'!F16,2) -> 0 | I16: =MID(A16,1,1) -> 6
A17: =FIXED('Balance N-1'!A17,0,1) -> 61911000 | B17: =+'Balance N-1'!B17 -> DEA FRAIS CONSTITUTION | C17: =ROUND('Balance N-1'!#REF!,2) -> #REF! | D17: =ROUND('Balance N-1'!#REF!,2) -> #REF! | E17: =ROUND('Balance N-1'!C17,2) -> 694.37 | F17: =ROUND('Balance N-1'!D17,2) -> 0 | G17: =ROUND('Balance N-1'!E17,2) -> 694.37 | H17: =ROUND('Balance N-1'!F17,2) -> 0 | I17: =MID(A17,1,1) -> 6
A18: =FIXED('Balance N-1'!A18,0,1) -> 0 | B18: =+'Balance N-1'!B18 -> 0 | C18: =ROUND('Balance N-1'!#REF!,2) -> #REF! | D18: =ROUND('Balance N-1'!#REF!,2) -> #REF! | E18: =ROUND('Balance N-1'!C18,2) -> 0 | F18: =ROUND('Balance N-1'!D18,2) -> 0 | G18: =ROUND('Balance N-1'!E18,2) -> 0 | H18: =ROUND('Balance N-1'!F18,2) -> 0 | I18: =MID(A18,1,1) -> 0
A19: =FIXED('Balance N-1'!A19,0,1) -> 0 | B19: =+'Balance N-1'!B19 -> 0 | C19: =ROUND('Balance N-1'!#REF!,2) -> #REF! | D19: =ROUND('Balance N-1'!#REF!,2) -> #REF! | E19: =ROUND('Balance N-1'!C19,2) -> 0 | F19: =ROUND('Balance N-1'!D19,2) -> 0 | G19: =ROUND('Balance N-1'!E19,2) -> 0 | H19: =ROUND('Balance N-1'!F19,2) -> 0 | I19: =MID(A19,1,1) -> 0
A20: =FIXED('Balance N-1'!A20,0,1) -> 0 | B20: =+'Balance N-1'!B20 -> 0 | C20: =ROUND('Balance N-1'!#REF!,2) -> #REF! | D20: =ROUND('Balance N-1'!#REF!,2) -> #REF! | E20: =ROUND('Balance N-1'!C20,2) -> 0 | F20: =ROUND('Balance N-1'!D20,2) -> 0 | G20: =ROUND('Balance N-1'!E20,2) -> 0 | H20: =ROUND('Balance N-1'!F20,2) -> 0 | I20: =MID(A20,1,1) -> 0
A21: =FIXED('Balance N-1'!A21,0,1) -> 0 | B21: =+'Balance N-1'!B21 -> 0 | C21: =ROUND('Balance N-1'!#REF!,2) -> #REF! | D21: =ROUND('Balance N-1'!#REF!,2) -> #REF! | E21: =ROUND('Balance N-1'!C21,2) -> 0 | F21: =ROUND('Balance N-1'!D21,2) -> 0 | G21: =ROUND('Balance N-1'!E21,2) -> 0 | H21: =ROUND('Balance N-1'!F21,2) -> 0 | I21: =MID(A21,1,1) -> 0
A22: =FIXED('Balance N-1'!A22,0,1) -> 0 | B22: =+'Balance N-1'!B22 -> 0 | C22: =ROUND('Balance N-1'!#REF!,2) -> #REF! | D22: =ROUND('Balance N-1'!#REF!,2) -> #REF! | E22: =ROUND('Balance N-1'!C22,2) -> 0 | F22: =ROUND('Balance N-1'!D22,2) -> 0 | G22: =ROUND('Balance N-1'!E22,2) -> 0 | H22: =ROUND('Balance N-1'!F22,2) -> 0 | I22: =MID(A22,1,1) -> 0
... A616: =FIXED('Balance N-1'!A616,0,1) -> 0 | B616: =+'Balance N-1'!B616 -> 0 | C616: =ROUND('Balance N-1'!#REF!,2) -> #REF! | D616: =ROUND('Balance N-1'!#REF!,2) -> #REF! | E616: =ROUND('Balance N-1'!C616,2) -> 0 | F616: =ROUND('Balance N-1'!D616,2) -> 0 | G616: =ROUND('Balance N-1'!E616,2) -> 0 | H616: =ROUND('Balance N-1'!F616,2) -> 0 | I616: =MID(A616,1,1) -> 0
C617: =ROUND('Balance N-1'!#REF!,2) -> #REF! | D617: =ROUND('Balance N-1'!#REF!,2) -> #REF! | E617: =ROUND('Balance N-1'!C617,2) -> 0 | F617: =ROUND('Balance N-1'!D617,2) -> 0 | G617: =ROUND('Balance N-1'!E617,2) -> 0 | H617: =ROUND('Balance N-1'!F617,2) -> 0

Sheet T1 Bilan
A1: Tableau n° 1
C2: BILAN (ACTIF)
C3: (modèle normal) | E3: Exercice clos le : | G3: =Couverture!E15 -> 31/12/2022
B4: ACTIF | D4: Exercice | G4: Exercice Précédent
D5: Amortissement
C6: Brut | D6: et | E6: Net | G6: Net
D7: provisions
B8: IMMOBILISATIONS EN NON VALEURS (A) | C8: =SUM(C9:C11) -> 5000 | D8: =SUM(D9:D11) -> 2360.87 | E8: =SUM(E9:E11) -> 2639.13 | G8: =SUM(G9:G11) -> 4305.63
B9: * Frais préliminaires | C9: =SUMIF('Balance N Retraitée'!A:A,"211*",'Balance N Retraitée'!G:G)-SUMIF('Balance N Retraitée'!A:A,"211*",'Balance N Retraitée'!H:H) -> 5000 | D9: =(SUMIF('Balance N Retraitée'!A:A,"2811*",'Balance N Retraitée'!H:H)-SUMIF('Balance N Retraitée'!A:A,"2811*",'Balance N Retraitée'!G:G))+(SUMIF('Balance N Retraitée'!A:A,"2911*",'Balance N Retraitée'!H:H)-SUMIF('Balance N Retraitée'!A:A,"2911*",'Balance N Retraitée'!G:G)) -> 2360.87 | E9: =+C9-D9 -> 2639.13 | G9: =(SUMIF('Balance N-1 Retraitée'!A:A,"211*",'Balance N-1 Retraitée'!G:G)-SUMIF('Balance N-1 Retraitée'!A:A,"211*",'Balance N-1 Retraitée'!H:H))-(SUMIF('Balance N-1 Retraitée'!A:A,"2811*",'Balance N-1 Retraitée'!H:H)-SUMIF('Balance N-1 Retraitée'!A:A,"2811*",'Balance N-1 Retraitée'!G:G))-(SUMIF('Balance N-1 Retraitée'!A:A,"2911*",'Balance N-1 Retraitée'!H:H)-SUMIF('Balance N-1 Retraitée'!A:A,"2911*",'Balance N-1 Retraitée'!G:G)) -> 4305.63
B10: * Charges à repartir sur plusieurs exercices | C10: =SUMIF('Balance N Retraitée'!A:A,"212*",'Balance N Retraitée'!G:G)-SUMIF('Balance N Retraitée'!A:A,"212*",'Balance N Retraitée'!H:H) -> 0 | D10: =(SUMIF('Balance N Retraitée'!A:A,"2812*",'Balance N Retraitée'!H:H)-SUMIF('Balance N Retraitée'!A:A,"2812*",'Balance N Retraitée'!G:G))+(SUMIF('Balance N Retraitée'!A:A,"2912*",'Balance N Retraitée'!H:H)-SUMIF('Balance N Retraitée'!A:A,"2912*",'Balance N Retraitée'!G:G)) -> 0 | E10: =+C10-D10 -> 0 | G10: =(SUMIF('Balance N-1 Retraitée'!A:A,"212*",'Balance N-1 Retraitée'!G:G)-SUMIF('Balance N-1 Retraitée'!A:A,"212*",'Balance N-1 Retraitée'!H:H))-(SUMIF('Balance N-1 Retraitée'!A:A,"2812*",'Balance N-1 Retraitée'!H:H)-SUMIF('Balance N-1 Retraitée'!A:A,"2812*",'Balance N-1 Retraitée'!G:G))-(SUMIF('Balance N-1 Retraitée'!A:A,"2912*",'Balance N-1 Retraitée'!H:H)-SUMIF('Balance N-1 Retraitée'!A:A,"2912*",'Balance N-1 Retraitée'!G:G)) -> 0
A11: s | B11: * Primes de remboursement des obligations | C11: =SUMIF('Balance N Retraitée'!A:A,"213*",'Balance N Retraitée'!G:G)-SUMIF('Balance N Retraitée'!A:A,"213*",'Balance N Retraitée'!H:H) -> 0 | D11: =(SUMIF('Balance N Retraitée'!A:A,"2813*",'Balance N Retraitée'!H:H)-SUMIF('Balance N Retraitée'!A:A,"2813*",'Balance N Retraitée'!G:G))+(SUMIF('Balance N Retraitée'!A:A,"2913*",'Balance N Retraitée'!H:H)-SUMIF('Balance N Retraitée'!A:A,"2913*",'Balance N Retraitée'!G:G)) -> 0 | E11: =+C13-D13 -> 0 | G11: =(SUMIF('Balance N-1 Retraitée'!A:A,"213*",'Balance N-1 Retraitée'!G:G)-SUMIF('Balance N-1 Retraitée'!A:A,"213*",'Balance N-1 Retraitée'!H:H))-(SUMIF('Balance N-1 Retraitée'!A:A,"2813*",'Balance N-1 Retraitée'!H:H)-SUMIF('Balance N-1 Retraitée'!A:A,"2813*",'Balance N-1 Retraitée'!G:G))-(SUMIF('Balance N-1 Retraitée'!A:A,"2913*",'Balance N-1 Retraitée'!H:H)-SUMIF('Balance N-1 Retraitée'!A:A,"2913*",'Balance N-1 Retraitée'!G:G)) -> 0
A12: e | B12: IMMOBILISATIONS INCORPORELLES (B) | C12: =SUM(C13:C16) -> 0 | D12: =SUM(D13:D16) -> 0 | E12: =SUM(E13:E16) -> 0 | G12: =SUM(G13:G16) -> 0
A13: é | B13: * Immobilisation en recherche et développement | C13: =SUMIF('Balance N Retraitée'!A:A,"221*",'Balance N Retraitée'!G:G)-SUMIF('Balance N Retraitée'!A:A,"221*",'Balance N Retraitée'!H:H) -> 0 | D13: =(SUMIF('Balance N Retraitée'!A:A,"2821*",'Balance N Retraitée'!H:H)-SUMIF('Balance N Retraitée'!A:A,"2821*",'Balance N Retraitée'!G:G))+(SUMIF('Balance N Retraitée'!A:A,"2921*",'Balance N Retraitée'!H:H)-SUMIF('Balance N Retraitée'!A:A,"2921*",'Balance N Retraitée'!G:G)) -> 0 | E13: =+C13-D13 -> 0 | G13: =(SUMIF('Balance N-1 Retraitée'!A:A,"221*",'Balance N-1 Retraitée'!G:G)-SUMIF('Balance N-1 Retraitée'!A:A,"221*",'Balance N-1 Retraitée'!H:H))-(SUMIF('Balance N-1 Retraitée'!A:A,"2821*",'Balance N-1 Retraitée'!H:H)-SUMIF('Balance N-1 Retraitée'!A:A,"2821*",'Balance N-1 Retraitée'!G:G))-(SUMIF('Balance N-1 Retraitée'!A:A,"2921*",'Balance N-1 Retraitée'!H:H)-SUMIF('Balance N-1 Retraitée'!A:A,"2921*",'Balance N-1 Retraitée'!G:G)) -> 0
A14: s | B14: * Brevets, marques, droits et valeurs similaires | C14: =SUMIF('Balance N Retraitée'!A:A,"222*",'Balance N Retraitée'!G:G)-SUMIF('Balance N Retraitée'!A:A,"222*",'Balance N Retraitée'!H:H) -> 0 | D14: =(SUMIF('Balance N Retraitée'!A:A,"2822*",'Balance N Retraitée'!H:H)-SUMIF('Balance N Retraitée'!A:A,"2822*",'Balance N Retraitée'!G:G))+(SUMIF('Balance N Retraitée'!A:A,"2922*",'Balance N Retraitée'!H:H)-SUMIF('Balance N Retraitée'!A:A,"2922*",'Balance N Retraitée'!G:G)) -> 0 | E14: =+C14-D14 -> 0 | G14: =(SUMIF('Balance N-1 Retraitée'!A:A,"222*",'Balance N-1 Retraitée'!G:G)-SUMIF('Balance N-1 Retraitée'!A:A,"222*",'Balance N-1 Retraitée'!H:H))-(SUMIF('Balance N-1 Retraitée'!A:A,"2822*",'Balance N-1 Retraitée'!H:H)-SUMIF('Balance N-1 Retraitée'!A:A,"2822*",'Balance N-1 Retraitée'!G:G))-(SUMIF('Balance N-1 Retraitée'!A:A,"2922*",'Balance N-1 Retraitée'!H:H)-SUMIF('Balance N-1 Retraitée'!A:A,"2922*",'Balance N-1 Retraitée'!G:G)) -> 0
A15: i | B15: * Fonds commercial | C15: =SUMIF('Balance N Retraitée'!A:A,"223*",'Balance N Retraitée'!G:G)-SUMIF('Balance N Retraitée'!A:A,"223*",'Balance N Retraitée'!H:H) -> 0 | D15: =(SUMIF('Balance N Retraitée'!A:A,"2823*",'Balance N Retraitée'!H:H)-SUMIF('Balance N Retraitée'!A:A,"2823*",'Balance N Retraitée'!G:G))+(SUMIF('Balance N Retraitée'!A:A,"2923*",'Balance N Retraitée'!H:H)-SUMIF('Balance N Retraitée'!A:A,"2923*",'Balance N Retraitée'!G:G)) -> 0 | E15: =+C15-D15 -> 0 | G15: =(SUMIF('Balance N-1 Retraitée'!A:A,"223*",'Balance N-1 Retraitée'!G:G)-SUMIF('Balance N-1 Retraitée'!A:A,"223*",'Balance N-1 Retraitée'!H:H))-(SUMIF('Balance N-1 Retraitée'!A:A,"2823*",'Balance N-1 Retraitée'!H:H)-SUMIF('Balance N-1 Retraitée'!A:A,"2823*",'Balance N-1 Retraitée'!G:G))-(SUMIF('Balance N-1 Retraitée'!A:A,"2923*",'Balance N-1 Retraitée'!H:H)-SUMIF('Balance N-1 Retraitée'!A:A,"2923*",'Balance N-1 Retraitée'!G:G)) -> 0
A16: l | B16: * Autres immobilisations incorporelles | C16: =SUMIF('Balance N Retraitée'!A:A,"228*",'Balance N Retraitée'!G:G)-SUMIF('Balance N Retraitée'!A:A,"228*",'Balance N Retraitée'!H:H) -> 0 | D16: =(SUMIF('Balance N Retraitée'!A:A,"2828*",'Balance N Retraitée'!H:H)-SUMIF('Balance N Retraitée'!A:A,"2828*",'Balance N Retraitée'!G:G))+(SUMIF('Balance N Retraitée'!A:A,"2928*",'Balance N Retraitée'!H:H)-SUMIF('Balance N Retraitée'!A:A,"2928*",'Balance N Retraitée'!G:G)) -> 0 | E16: =+C16-D16 -> 0 | G16: =(SUMIF('Balance N-1 Retraitée'!A:A,"228*",'Balance N-1 Retraitée'!G:G)-SUMIF('Balance N-1 Retraitée'!A:A,"228*",'Balance N-1 Retraitée'!H:H))-(SUMIF('Balance N-1 Retraitée'!A:A,"2828*",'Balance N-1 Retraitée'!H:H)-SUMIF('Balance N-1 Retraitée'!A:A,"2828*",'Balance N-1 Retraitée'!G:G))-(SUMIF('Balance N-1 Retraitée'!A:A,"2928*",'Balance N-1 Retraitée'!H:H)-SUMIF('Balance N-1 Retraitée'!A:A,"2928*",'Balance N-1 Retraitée'!G:G)) -> 0
A17: i | B17: IMMOBILISATIONS CORPORELLES (C) | C17: =SUM(C18:C24) -> 1588527.6 | D17: =SUM(D18:D24) -> 171177.26 | E17: =SUM(E18:E24) -> 1417350.3 | G17: =SUM(G18:G24) -> 0
A18: b | B18: * Terrains | C18: =SUMIF('Balance N Retraitée'!A:A,"231*",'Balance N Retraitée'!G:G)-SUMIF('Balance N Retraitée'!A:A,"231*",'Balance N Retraitée'!H:H) -> 0 | D18: =(SUMIF('Balance N Retraitée'!A:A,"2831*",'Balance N Retraitée'!H:H)-SUMIF('Balance N Retraitée'!A:A,"2831*",'Balance N Retraitée'!G:G))+(SUMIF('Balance N Retraitée'!A:A,"2931*",'Balance N Retraitée'!H:H)-SUMIF('Balance N Retraitée'!A:A,"2931*",'Balance N Retraitée'!G:G)) -> 0 | E18: =+C18-D18 -> 0 | G18: =(SUMIF('Balance N-1 Retraitée'!A:A,"231*",'Balance N-1 Retraitée'!G:G)-SUMIF('Balance N-1 Retraitée'!A:A,"231*",'Balance N-1 Retraitée'!H:H))-(SUMIF('Balance N-1 Retraitée'!A:A,"2831*",'Balance N-1 Retraitée'!H:H)-SUMIF('Balance N-1 Retraitée'!A:A,"2831*",'Balance N-1 Retraitée'!G:G))-(SUMIF('Balance N-1 Retraitée'!A:A,"2931*",'Balance N-1 Retraitée'!H:H)-SUMIF('Balance N-1 Retraitée'!A:A,"2931*",'Balance N-1 Retraitée'!G:G)) -> 0
A19: o | B19: * Constructions | C19: =SUMIF('Balance N Retraitée'!A:A,"232*",'Balance N Retraitée'!G:G)-SUMIF('Balance N Retraitée'!A:A,"232*",'Balance N Retraitée'!H:H) -> 9700 | D19: =(SUMIF('Balance N Retraitée'!A:A,"2832*",'Balance N Retraitée'!H:H)-SUMIF('Balance N Retraitée'!A:A,"2832*",'Balance N Retraitée'!G:G))+(SUMIF('Balance N Retraitée'!A:A,"2932*",'Balance N Retraitée'!H:H)-SUMIF('Balance N Retraitée'!A:A,"2932*",'Balance N Retraitée'!G:G)) -> 1215 | E19: =+C19-D19 -> 8485 | G19: =(SUMIF('Balance N-1 Retraitée'!A:A,"232*",'Balance N-1 Retraitée'!G:G)-SUMIF('Balance N-1 Retraitée'!A:A,"232*",'Balance N-1 Retraitée'!H:H))-(SUMIF('Balance N-1 Retraitée'!A:A,"2832*",'Balance N-1 Retraitée'!H:H)-SUMIF('Balance N-1 Retraitée'!A:A,"2832*",'Balance N-1 Retraitée'!G:G))-(SUMIF('Balance N-1 Retraitée'!A:A,"2932*",'Balance N-1 Retraitée'!H:H)-SUMIF('Balance N-1 Retraitée'!A:A,"2932*",'Balance N-1 Retraitée'!G:G)) -> 0
A20: m | B20: * Installations techniques, matériel et outillage | C20: =SUMIF('Balance N Retraitée'!A:A,"233*",'Balance N Retraitée'!G:G)-SUMIF('Balance N Retraitée'!A:A,"233*",'Balance N Retraitée'!H:H) -> 0 | D20: =(SUMIF('Balance N Retraitée'!A:A,"2833*",'Balance N Retraitée'!H:H)-SUMIF('Balance N Retraitée'!A:A,"2833*",'Balance N Retraitée'!G:G))+(SUMIF('Balance N Retraitée'!A:A,"2933*",'Balance N Retraitée'!H:H)-SUMIF('Balance N Retraitée'!A:A,"2933*",'Balance N Retraitée'!G:G)) -> 0 | E20: =+C20-D20 -> 0 | G20: =(SUMIF('Balance N-1 Retraitée'!A:A,"233*",'Balance N-1 Retraitée'!G:G)-SUMIF('Balance N-1 Retraitée'!A:A,"233*",'Balance N-1 Retraitée'!H:H))-(SUMIF('Balance N-1 Retraitée'!A:A,"2833*",'Balance N-1 Retraitée'!H:H)-SUMIF('Balance N-1 Retraitée'!A:A,"2833*",'Balance N-1 Retraitée'!G:G))-(SUMIF('Balance N-1 Retraitée'!A:A,"2933*",'Balance N-1 Retraitée'!H:H)-SUMIF('Balance N-1 Retraitée'!A:A,"2933*",'Balance N-1 Retraitée'!G:G)) -> 0
A21: m | B21: * Matériel transport | C21: =SUMIF('Balance N Retraitée'!A:A,"234*",'Balance N Retraitée'!G:G)-SUMIF('Balance N Retraitée'!A:A,"234*",'Balance N Retraitée'!H:H) -> 1578827.6 | D21: =(SUMIF('Balance N Retraitée'!A:A,"2834*",'Balance N Retraitée'!H:H)-SUMIF('Balance N Retraitée'!A:A,"2834*",'Balance N Retraitée'!G:G))+(SUMIF('Balance N Retraitée'!A:A,"2934*",'Balance N Retraitée'!H:H)-SUMIF('Balance N Retraitée'!A:A,"2934*",'Balance N Retraitée'!G:G)) -> 169962.26 | E21: =+C21-D21 -> 1408865.3 | G21: =(SUMIF('Balance N-1 Retraitée'!A:A,"234*",'Balance N-1 Retraitée'!G:G)-SUMIF('Balance N-1 Retraitée'!A:A,"234*",'Balance N-1 Retraitée'!H:H))-(SUMIF('Balance N-1 Retraitée'!A:A,"2834*",'Balance N-1 Retraitée'!H:H)-SUMIF('Balance N-1 Retraitée'!A:A,"2834*",'Balance N-1 Retraitée'!G:G))-(SUMIF('Balance N-1 Retraitée'!A:A,"2934*",'Balance N-1 Retraitée'!H:H)-SUMIF('Balance N-1 Retraitée'!A:A,"2934*",'Balance N-1 Retraitée'!G:G)) -> 0
A22: I | B22: * Mobilier, matériel de bureau et aménagements divers | C22: =SUMIF('Balance N Retraitée'!A:A,"235*",'Balance N Retraitée'!G:G)-SUMIF('Balance N Retraitée'!A:A,"235*",'Balance N Retraitée'!H:H) -> 0 | D22: =(SUMIF('Balance N Retraitée'!A:A,"2835*",'Balance N Retraitée'!H:H)-SUMIF('Balance N Retraitée'!A:A,"2835*",'Balance N Retraitée'!G:G))+(SUMIF('Balance N Retraitée'!A:A,"2935*",'Balance N Retraitée'!H:H)-SUMIF('Balance N Retraitée'!A:A,"2935*",'Balance N Retraitée'!G:G)) -> 0 | E22: =+C22-D22 -> 0 | G22: =(SUMIF('Balance N-1 Retraitée'!A:A,"235*",'Balance N-1 Retraitée'!G:G)-SUMIF('Balance N-1 Retraitée'!A:A,"235*",'Balance N-1 Retraitée'!H:H))-(SUMIF('Balance N-1 Retraitée'!A:A,"2835*",'Balance N-1 Retraitée'!H:H)-SUMIF('Balance N-1 Retraitée'!A:A,"2835*",'Balance N-1 Retraitée'!G:G))-(SUMIF('Balance N-1 Retraitée'!A:A,"2935*",'Balance N-1 Retraitée'!H:H)-SUMIF('Balance N-1 Retraitée'!A:A,"2935*",'Balance N-1 Retraitée'!G:G)) -> 0
B23: * Autres immobilisations corporelles | C23: =SUMIF('Balance N Retraitée'!A:A,"236*",'Balance N Retraitée'!G:G)-SUMIF('Balance N Retraitée'!A:A,"236*",'Balance N Retraitée'!H:H) -> 0 | D23: =(SUMIF('Balance N Retraitée'!A:A,"2836*",'Balance N Retraitée'!H:H)-SUMIF('Balance N Retraitée'!A:A,"2836*",'Balance N Retraitée'!G:G))+(SUMIF('Balance N Retraitée'!A:A,"2936*",'Balance N Retraitée'!H:H)-SUMIF('Balance N Retraitée'!A:A,"2936*",'Balance N Retraitée'!G:G)) -> 0 | E23: =+C23-D23 -> 0 | G23: =(SUMIF('Balance N-1 Retraitée'!A:A,"236*",'Balance N-1 Retraitée'!G:G)-SUMIF('Balance N-1 Retraitée'!A:A,"236*",'Balance N-1 Retraitée'!H:H))-(SUMIF('Balance N-1 Retraitée'!A:A,"2836*",'Balance N-1 Retraitée'!H:H)-SUMIF('Balance N-1 Retraitée'!A:A,"2836*",'Balance N-1 Retraitée'!G:G))-(SUMIF('Balance N-1 Retraitée'!A:A,"2936*",'Balance N-1 Retraitée'!H:H)-SUMIF('Balance N-1 Retraitée'!A:A,"2936*",'Balance N-1 Retraitée'!G:G)) -> 0
A24: s | B24: * Immobilisations corporelles en cours | C24: =SUMIF('Balance N Retraitée'!A:A,"238*",'Balance N Retraitée'!G:G)-SUMIF('Balance N Retraitée'!A:A,"238*",'Balance N Retraitée'!H:H) -> 0 | D24: =(SUMIF('Balance N Retraitée'!A:A,"2838*",'Balance N Retraitée'!H:H)-SUMIF('Balance N Retraitée'!A:A,"2838*",'Balance N Retraitée'!G:G))+(SUMIF('Balance N Retraitée'!A:A,"2938*",'Balance N Retraitée'!H:H)-SUMIF('Balance N Retraitée'!A:A,"2938*",'Balance N Retraitée'!G:G)) -> 0 | E24: =+C24-D24 -> 0 | G24: =(SUMIF('Balance N-1 Retraitée'!A:A,"238*",'Balance N-1 Retraitée'!G:G)-SUMIF('Balance N-1 Retraitée'!A:A,"238*",'Balance N-1 Retraitée'!H:H))-(SUMIF('Balance N-1 Retraitée'!A:A,"2838*",'Balance N-1 Retraitée'!H:H)-SUMIF('Balance N-1 Retraitée'!A:A,"2838*",'Balance N-1 Retraitée'!G:G))-(SUMIF('Balance N-1 Retraitée'!A:A,"2938*",'Balance N-1 Retraitée'!H:H)-SUMIF('Balance N-1 Retraitée'!A:A,"2938*",'Balance N-1 Retraitée'!G:G)) -> 0
A25: r | B25: IMMOBILISATIONS FINANCIERES (D) | C25: =SUM(C26:C29) -> 0 | D25: =SUM(D26:D29) -> 0 | E25: =SUM(E26:E29) -> 0 | G25: =SUM(G26:G29) -> 0
A26: u | B26: * Prêts immobilisés | C26: =SUMIF('Balance N Retraitée'!A:A,"241*",'Balance N Retraitée'!G:G)-SUMIF('Balance N Retraitée'!A:A,"241*",'Balance N Retraitée'!H:H) -> 0 | D26: =(SUMIF('Balance N Retraitée'!A:A,"2941*",'Balance N Retraitée'!H:H)-SUMIF('Balance N Retraitée'!A:A,"2941*",'Balance N Retraitée'!G:G)) -> 0 | E26: =+C26-D26 -> 0 | G26: =(SUMIF('Balance N-1 Retraitée'!A:A,"241*",'Balance N-1 Retraitée'!G:G)-SUMIF('Balance N-1 Retraitée'!A:A,"241*",'Balance N-1 Retraitée'!H:H))-(SUMIF('Balance N-1 Retraitée'!A:A,"2941*",'Balance N-1 Retraitée'!H:H)-SUMIF('Balance N-1 Retraitée'!A:A,"2941*",'Balance N-1 Retraitée'!G:G)) -> 0
A27: e | B27: * Autres créances financières | C27: =SUMIF('Balance N Retraitée'!A:A,"248*",'Balance N Retraitée'!G:G)-SUMIF('Balance N Retraitée'!A:A,"248*",'Balance N Retraitée'!H:H) -> 0 | D27: =(SUMIF('Balance N Retraitée'!A:A,"2948*",'Balance N Retraitée'!H:H)-SUMIF('Balance N Retraitée'!A:A,"2948*",'Balance N Retraitée'!G:G)) -> 0 | E27: =+C27-D27 -> 0 | G27: =(SUMIF('Balance N-1 Retraitée'!A:A,"248*",'Balance N-1 Retraitée'!G:G)-SUMIF('Balance N-1 Retraitée'!A:A,"248*",'Balance N-1 Retraitée'!H:H))-(SUMIF('Balance N-1 Retraitée'!A:A,"2948*",'Balance N-1 Retraitée'!H:H)-SUMIF('Balance N-1 Retraitée'!A:A,"2948*",'Balance N-1 Retraitée'!G:G)) -> 0
A28: l | B28: * Titres de participation | C28: =SUMIF('Balance N Retraitée'!A:A,"251*",'Balance N Retraitée'!G:G)-SUMIF('Balance N Retraitée'!A:A,"251*",'Balance N Retraitée'!H:H) -> 0 | D28: =(SUMIF('Balance N Retraitée'!A:A,"2951*",'Balance N Retraitée'!H:H)-SUMIF('Balance N Retraitée'!A:A,"2951*",'Balance N Retraitée'!G:G)) -> 0 | E28: =+C28-D28 -> 0 | G28: =(SUMIF('Balance N-1 Retraitée'!A:A,"251*",'Balance N-1 Retraitée'!G:G)-SUMIF('Balance N-1 Retraitée'!A:A,"251*",'Balance N-1 Retraitée'!H:H))-(SUMIF('Balance N-1 Retraitée'!A:A,"2951*",'Balance N-1 Retraitée'!H:H)-SUMIF('Balance N-1 Retraitée'!A:A,"2951*",'Balance N-1 Retraitée'!G:G)) -> 0
A29: a | B29: * Autres titres immobilisés | C29: =SUMIF('Balance N Retraitée'!A:A,"258*",'Balance N Retraitée'!G:G)-SUMIF('Balance N Retraitée'!A:A,"258*",'Balance N Retraitée'!H:H) -> 0 | D29: =(SUMIF('Balance N Retraitée'!A:A,"2958*",'Balance N Retraitée'!H:H)-SUMIF('Balance N Retraitée'!A:A,"2958*",'Balance N Retraitée'!G:G)) -> 0 | E29: =+C29-D29 -> 0 | G29: =(SUMIF('Balance N-1 Retraitée'!A:A,"258*",'Balance N-1 Retraitée'!G:G)-SUMIF('Balance N-1 Retraitée'!A:A,"258*",'Balance N-1 Retraitée'!H:H))-(SUMIF('Balance N-1 Retraitée'!A:A,"2958*",'Balance N-1 Retraitée'!H:H)-SUMIF('Balance N-1 Retraitée'!A:A,"2958*",'Balance N-1 Retraitée'!G:G)) -> 0
A30: V | B30: ECARTS DE CONVERSION -ACTIF (E) | C30: 0 | E30: =SUM(E31:E32) -> 0 | G30: =SUM(G31:G32) -> 0
B31: * Diminution des créances immobilisées | C31: =SUMIF('Balance N Retraitée'!A:A,"271*",'Balance N Retraitée'!G:G)-SUMIF('Balance N Retraitée'!A:A,"271*",'Balance N Retraitée'!H:H) -> 0 | E31: =C31 -> 0 | G31: =SUMIF('Balance N-1 Retraitée'!A:A,"271*",'Balance N-1 Retraitée'!G:G)-SUMIF('Balance N-1 Retraitée'!A:A,"271*",'Balance N-1 Retraitée'!H:H) -> 0
B32: * Augmentation des dettes financières | C32: =SUMIF('Balance N Retraitée'!A:A,"272*",'Balance N Retraitée'!G:G)-SUMIF('Balance N Retraitée'!A:A,"272*",'Balance N Retraitée'!H:H) -> 0 | E32: =C32 -> 0 | G32: =SUMIF('Balance N-1 Retraitée'!A:A,"272*",'Balance N-1 Retraitée'!G:G)-SUMIF('Balance N-1 Retraitée'!A:A,"272*",'Balance N-1 Retraitée'!H:H) -> 0
B33: TOTAL I (A+B+C+D+E) | C33: =+C8+C12+C17+C25+C30 -> 1593527.6 | D33: =+D8+D12+D17+D25+D30 -> 173538.13 | E33: =+E8+E12+E17+E25+E30 -> 1419989.4 | G33: =+G8+G12+G17+G25+G30 -> 4305.63
B35: STOCKS (F) | C35: =SUM(C36:C40) -> 0 | D35: =SUM(D36:D40) -> 0 | E35: =SUM(E36:E40) -> 0 | G35: =SUM(G36:G40) -> 0
B36: * Marchandises | C36: =SUMIF('Balance N Retraitée'!A:A,"311*",'Balance N Retraitée'!G:G)-SUMIF('Balance N Retraitée'!A:A,"311*",'Balance N Retraitée'!H:H) -> 0 | D36: =SUMIF('Balance N Retraitée'!A:A,"3911*",'Balance N Retraitée'!H:H)-SUMIF('Balance N Retraitée'!A:A,"3911*",'Balance N Retraitée'!G:G) -> 0 | E36: =+C36-D36 -> 0 | G36: =(SUMIF('Balance N-1 Retraitée'!A:A,"311*",'Balance N-1 Retraitée'!G:G)-SUMIF('Balance N-1 Retraitée'!A:A,"311*",'Balance N-1 Retraitée'!H:H))-(SUMIF('Balance N-1 Retraitée'!A:A,"3911*",'Balance N-1 Retraitée'!H:H)-SUMIF('Balance N-1 Retraitée'!A:A,"3911*",'Balance N-1 Retraitée'!G:G)) -> 0
B37: * Matières et fournitures, consommables | C37: =SUMIF('Balance N Retraitée'!A:A,"312*",'Balance N Retraitée'!G:G)-SUMIF('Balance N Retraitée'!A:A,"312*",'Balance N Retraitée'!H:H) -> 0 | D37: =SUMIF('Balance N Retraitée'!A:A,"3912*",'Balance N Retraitée'!H:H)-SUMIF('Balance N Retraitée'!A:A,"3912*",'Balance N Retraitée'!G:G) -> 0 | E37: =+C37-D37 -> 0 | G37: =(SUMIF('Balance N-1 Retraitée'!A:A,"312*",'Balance N-1 Retraitée'!G:G)-SUMIF('Balance N-1 Retraitée'!A:A,"312*",'Balance N-1 Retraitée'!H:H))-(SUMIF('Balance N-1 Retraitée'!A:A,"3912*",'Balance N-1 Retraitée'!H:H)-SUMIF('Balance N-1 Retraitée'!A:A,"3912*",'Balance N-1 Retraitée'!G:G)) -> 0
B38: * Produits en cours | C38: =SUMIF('Balance N Retraitée'!A:A,"313*",'Balance N Retraitée'!G:G)-SUMIF('Balance N Retraitée'!A:A,"313*",'Balance N Retraitée'!H:H) -> 0 | D38: =SUMIF('Balance N Retraitée'!A:A,"3913*",'Balance N Retraitée'!H:H)-SUMIF('Balance N Retraitée'!A:A,"3913*",'Balance N Retraitée'!G:G) -> 0 | E38: =+C38-D38 -> 0 | G38: =(SUMIF('Balance N-1 Retraitée'!A:A,"313*",'Balance N-1 Retraitée'!G:G)-SUMIF('Balance N-1 Retraitée'!A:A,"313*",'Balance N-1 Retraitée'!H:H))-(SUMIF('Balance N-1 Retraitée'!A:A,"3913*",'Balance N-1 Retraitée'!H:H)-SUMIF('Balance N-1 Retraitée'!A:A,"3913*",'Balance N-1 Retraitée'!G:G)) -> 0
B39: * produits intermédiaires et produits résiduels | C39: =SUMIF('Balance N Retraitée'!A:A,"314*",'Balance N Retraitée'!G:G)-SUMIF('Balance N Retraitée'!A:A,"314*",'Balance N Retraitée'!H:H) -> 0 | D39: =SUMIF('Balance N Retraitée'!A:A,"3914*",'Balance N Retraitée'!H:H)-SUMIF('Balance N Retraitée'!A:A,"3914*",'Balance N Retraitée'!G:G) -> 0 | E39: =+C39-D39 -> 0 | G39: =(SUMIF('Balance N-1 Retraitée'!A:A,"314*",'Balance N-1 Retraitée'!G:G)-SUMIF('Balance N-1 Retraitée'!A:A,"314*",'Balance N-1 Retraitée'!H:H))-(SUMIF('Balance N-1 Retraitée'!A:A,"3914*",'Balance N-1 Retraitée'!H:H)-SUMIF('Balance N-1 Retraitée'!A:A,"3914*",'Balance N-1 Retraitée'!G:G)) -> 0
B40: * Produits finis | C40: =SUMIF('Balance N Retraitée'!A:A,"315*",'Balance N Retraitée'!G:G)-SUMIF('Balance N Retraitée'!A:A,"315*",'Balance N Retraitée'!H:H) -> 0 | D40: =SUMIF('Balance N Retraitée'!A:A,"3915*",'Balance N Retraitée'!H:H)-SUMIF('Balance N Retraitée'!A:A,"3915*",'Balance N Retraitée'!G:G) -> 0 | E40: =+C40-D40 -> 0 | G40: =(SUMIF('Balance N-1 Retraitée'!A:A,"315*",'Balance N-1 Retraitée'!G:G)-SUMIF('Balance N-1 Retraitée'!A:A,"315*",'Balance N-1 Retraitée'!H:H))-(SUMIF('Balance N-1 Retraitée'!A:A,"3915*",'Balance N-1 Retraitée'!H:H)-SUMIF('Balance N-1 Retraitée'!A:A,"3915*",'Balance N-1 Retraitée'!G:G)) -> 0
B41: CREANCES DE L'ACTIF CIRCULANT (G) | C41: =SUM(C42:C48) -> 308800.72 | D41: =SUM(D42:D48) -> 0 | E41: =SUM(E42:E48) -> 308800.72 | G41: =SUM(G42:G48) -> 34.53
...

Sheet T2 CPC
A1: Tableau n° 2
A2: COMPTE DE PRODUITS ET CHARGES (hors taxes)
A3: (modèle normal)
D4: Exercice du : | E4: =+Couverture!C15 -> 44562 | F4: =+Couverture!E15 -> 31/12/2022
D5: OPERATIONS
D6: Propres à l'exercice | E6: concernant les | F6: TOTAUX DE | G6: TOTAUX DE
C7: NATURE | E7: exercices précédent | F7: L'EXERCICE | G7: L'EXERCICE
G8: PRECEDENT
D10: 1 | E10: 2 | F10: 3=2+1
A11: E | B11: I | C11: PRODUITS D'EXPLOITATION | D11: =SUM(D12:D18) -> 381666.67 | E11: =SUM(E12:E18) -> 0 | F11: =SUM(F12:F18) -> 381666.67 | G11: =SUM(G12:G18) -> 0
A12: X | C12: * Ventes de marchandises (en l'état) | D12: =SUMIF('Balance N Retraitée'!A:A,"711*",'Balance N Retraitée'!H:H)-SUMIF('Balance N Retraitée'!A:A,"711*",'Balance N Retraitée'!G:G)-E12 -> 0 | E12: =SUMIF('Balance N Retraitée'!A:A,"7118*",'Balance N Retraitée'!H:H)-SUMIF('Balance N Retraitée'!A:A,"7118*",'Balance N Retraitée'!G:G) -> 0 | F12: =+D12+E12 -> 0 | G12: =SUMIF('Balance N-1 Retraitée'!A:A,"711*",'Balance N-1 Retraitée'!H:H)-SUMIF('Balance N-1 Retraitée'!A:A,"711*",'Balance N-1 Retraitée'!G:G) -> 0
A13: P | C13: * Ventes de biens et services produits chiffre d'affaires | D13: =SUMIF('Balance N Retraitée'!A:A,"712*",'Balance N Retraitée'!H:H)-SUMIF('Balance N Retraitée'!A:A,"712*",'Balance N Retraitée'!G:G) -> 381666.67 | E13: =(SUMIF('Balance N Retraitée'!A:A,"7128*",'Balance N Retraitée'!H:H)-SUMIF('Balance N Retraitée'!A:A,"7128*",'Balance N Retraitée'!G:G))+(SUMIF('Balance N Retraitée'!A:A,"71298*",'Balance N Retraitée'!H:H)-SUMIF('Balance N Retraitée'!A:A,"71298*",'Balance N Retraitée'!G:G)) -> 0 | F13: =+D13+E13 -> 381666.67 | G13: =SUMIF('Balance N-1 Retraitée'!A:A,"712*",'Balance N-1 Retraitée'!H:H)-SUMIF('Balance N-1 Retraitée'!A:A,"712*",'Balance N-1 Retraitée'!G:G) -> 0
A14: L | C14: * Variation des stocks de produits (1) | D14: =SUMIF('Balance N Retraitée'!A:A,"713*",'Balance N Retraitée'!H:H)-SUMIF('Balance N Retraitée'!A:A,"713*",'Balance N Retraitée'!G:G)-E14 -> 0 | F14: =+D14+E14 -> 0 | G14: =SUMIF('Balance N-1 Retraitée'!A:A,"713*",'Balance N-1 Retraitée'!H:H)-SUMIF('Balance N-1 Retraitée'!A:A,"713*",'Balance N-1 Retraitée'!G:G) -> 0
A15: O | C15: * Immobilisations produites par l'entreprise pour elle-même | D15: =SUMIF('Balance N Retraitée'!A:A,"714*",'Balance N Retraitée'!H:H)-SUMIF('Balance N Retraitée'!A:A,"714*",'Balance N Retraitée'!G:G)-E15 -> 0 | E15: =SUMIF('Balance N Retraitée'!A:A,"7148*",'Balance N Retraitée'!H:H)-SUMIF('Balance N Retraitée'!A:A,"7148*",'Balance N Retraitée'!G:G) -> 0 | F15: =+D15+E15 -> 0 | G15: =SUMIF('Balance N-1 Retraitée'!A:A,"714*",'Balance N-1 Retraitée'!H:H)-SUMIF('Balance N-1 Retraitée'!A:A,"714*",'Balance N-1 Retraitée'!G:G) -> 0
A16: I | C16: * Subventions d'exploitation | D16: =SUMIF('Balance N Retraitée'!A:A,"716*",'Balance N Retraitée'!H:H)-SUMIF('Balance N Retraitée'!A:A,"716*",'Balance N Retraitée'!G:G)-E16 -> 0 | E16: =SUMIF('Balance N Retraitée'!A:A,"7168*",'Balance N Retraitée'!H:H)-SUMIF('Balance N Retraitée'!A:A,"7168*",'Balance N Retraitée'!G:G) -> 0 | F16: =+D16+E16 -> 0 | G16: =SUMIF('Balance N-1 Retraitée'!A:A,"716*",'Balance N-1 Retraitée'!H:H)-SUMIF('Balance N-1 Retraitée'!A:A,"716*",'Balance N-1 Retraitée'!G:G) -> 0
A17: T | C17: * Autres produits d'exploitation | D17: =SUMIF('Balance N Retraitée'!A:A,"718*",'Balance N Retraitée'!H:H)-SUMIF('Balance N Retraitée'!A:A,"718*",'Balance N Retraitée'!G:G)-E17 -> 0 | E17: =SUMIF('Balance N Retraitée'!A:A,"7188*",'Balance N Retraitée'!H:H)-SUMIF('Balance N Retraitée'!A:A,"7188*",'Balance N Retraitée'!G:G) -> 0 | F17: =+D17+E17 -> 0 | G17: =SUMIF('Balance N-1 Retraitée'!A:A,"718*",'Balance N-1 Retraitée'!H:H)-SUMIF('Balance N-1 Retraitée'!A:A,"718*",'Balance N-1 Retraitée'!G:G) -> 0
A18: A | C18: * Reprises d'exploitation; Transsferts de charges | D18: =SUMIF('Balance N Retraitée'!A:A,"719*",'Balance N Retraitée'!H:H)-SUMIF('Balance N Retraitée'!A:A,"719*",'Balance N Retraitée'!G:G)-E18 -> 0 | E18: =SUMIF('Balance N Retraitée'!A:A,"7198*",'Balance N Retraitée'!H:H)-SUMIF('Balance N Retraitée'!A:A,"7198*",'Balance N Retraitée'!G:G) -> 0 | F18: =+D18+E18 -> 0 | G18: =SUMIF('Balance N-1 Retraitée'!A:A,"719*",'Balance N-1 Retraitée'!H:H)-SUMIF('Balance N-1 Retraitée'!A:A,"719*",'Balance N-1 Retraitée'!G:G) -> 0
A19: T | C19: Total I | D19: =ROUND(SUM(D12:D18),2) -> 381666.67 | E19: =ROUND(SUM(E12:E18),2) -> 0 | F19: =ROUND(SUM(F12:F18),2) -> 381666.67 | G19: =ROUND(SUM(G12:G18),2) -> 0
A20: I | B20: II | C20: CHARGES D'EXPLOITATION | D20: =SUM(D21:D27) -> 313873.12 | E20: =SUM(E21:E27) -> 0 | F20: =SUM(F21:F27) -> 313873.12 | G20: =SUM(G21:G27) -> 18918.67
A21: O | C21: * Achats revendus(2) de marchandises | D21: =SUMIF('Balance N Retraitée'!A:A,"611*",'Balance N Retraitée'!G:G)-SUMIF('Balance N Retraitée'!A:A,"611*",'Balance N Retraitée'!H:H)-E21 -> 0 | E21: =SUMIF('Balance N Retraitée'!A:A,"6118*",'Balance N Retraitée'!G:G)-SUMIF('Balance N Retraitée'!A:A,"6118*",'Balance N Retraitée'!H:H) -> 0 | F21: =+D21+E21 -> 0 | G21: =SUMIF('Balance N-1 Retraitée'!A:A,"611*",'Balance N-1 Retraitée'!G:G)-SUMIF('Balance N-1 Retraitée'!A:A,"611*",'Balance N-1 Retraitée'!H:H) -> 0
A22: N | C22: * Achats consommés(2) de matières et fournitures | D22: =SUMIF('Balance N Retraitée'!A:A,"612*",'Balance N Retraitée'!G:G)-SUMIF('Balance N Retraitée'!A:A,"612*",'Balance N Retraitée'!H:H)-E22 -> 0 | E22: =(SUMIF('Balance N Retraitée'!A:A,"6128*",'Balance N Retraitée'!G:G)-SUMIF('Balance N Retraitée'!A:A,"6128*",'Balance N Retraitée'!H:H))+(SUMIF('Balance N Retraitée'!A:A,"61298*",'Balance N Retraitée'!G:G)-SUMIF('Balance N Retraitée'!A:A,"61298*",'Balance N Retraitée'!H:H)) -> 0 | F22: =+D22+E22 -> 0 | G22: =SUMIF('Balance N-1 Retraitée'!A:A,"612*",'Balance N-1 Retraitée'!G:G)-SUMIF('Balance N-1 Retraitée'!A:A,"612*",'Balance N-1 Retraitée'!H:H) -> 0
C23: * Autres charges externes | D23: =SUMIF('Balance N Retraitée'!A:A,"613*",'Balance N Retraitée'!G:G)-SUMIF('Balance N Retraitée'!A:A,"613*",'Balance N Retraitée'!H:H)+SUMIF('Balance N Retraitée'!A:A,"614*",'Balance N Retraitée'!G:G)-SUMIF('Balance N Retraitée'!A:A,"614*",'Balance N Retraitée'!H:H)-E23 -> 78665.81 | E23: =SUMIF('Balance N Retraitée'!A:A,"6148*",'Balance N Retraitée'!G:G)-SUMIF('Balance N Retraitée'!A:A,"6148*",'Balance N Retraitée'!H:H) -> 0 | F23: =+D23+E23 -> 78665.81 | G23: =SUMIF('Balance N-1 Retraitée'!A:A,"613*",'Balance N-1 Retraitée'!G:G)-SUMIF('Balance N-1 Retraitée'!A:A,"613*",'Balance N-1 Retraitée'!H:H)+SUMIF('Balance N-1 Retraitée'!A:A,"614*",'Balance N-1 Retraitée'!G:G)-SUMIF('Balance N-1 Retraitée'!A:A,"614*",'Balance N-1 Retraitée'!H:H) -> 5353.3
